Workbook

Sheet 说明
B2: T1 结构迷宫 · 集团总部费用 · 多表归并挑战
B4: 这份工作簿是什么
B5: 六个部门的 2026 年全年费用明细，六种完全不同的表格布局。全部为合成模拟数据（随机种子 20260901）。
B6: 「汇总视图」与「勾稽校验」中每个数字都是活公式，从六张异构明细表实时归并。
B8: 挑战点（不剧透具体位置）
B9: 1. 横竖转置：有的表月份在行上，有的在列上。
B10: 2. 小计行混在明细里：整列求和会重复计算。
B11: 3. 合并单元格：月份列为纵向合并，只有合并区第一行有值。
B12: 4. 一页两表：同一张工作表左右两块独立表格。
B13: 5. 标签不干净：月份带前导空格、项目名带尾随空格、同一项目多种写法（见「科目对照」）。
B14: 6. 负数红字冲销行、以及“看着像金额但绝不是金额”的干扰列。
B15: 另有隐藏列：有的藏着 consolidations 依赖的辅助公式，有的是纯干扰数据。
... B22: 金额单位：元，两位小数；月份均为 2026 年 1-12 月自然月；数据为合成模拟数据 [测算]。

Sheet 汇总视图
A1: 六部门费用归并（全部为活公式，修改明细表即实时变动）
B3: 月份 | C3: 销售部 | D3: 市场部 | E3: 后勤部 | F3: 人事部 | G3: 研发部 | H3: 行政部 | I3: 合计
B4: 1 | C4: =SUMPRODUCT((销售部!$A$3:$A$42=$B4)*销售部!$C$3:$C$42) -> 117590.99 | D4: =SUM(INDEX(市场部!$B$4:$M$9,0,$B4)) -> 297674.07 | E4: =SUMPRODUCT((后勤部!$A$4:$A$9=$B4)*后勤部!$C$4:$C$9)+SUMPRODUCT((后勤部!$E$4:$E$9=$B4)*后勤部!$G$4:$G$9) -> 8709.3 | F4: =SUMPRODUCT((人事部!$E$3:$E$38=$B4)*人事部!$C$3:$C$38) -> 651595.25 | G4: =SUMPRODUCT((TRIM(研发部!$A$3:$A$38)=$B4&"月")*研发部!$C$3:$C$38) -> 175086.23 | H4: =SUMPRODUCT((行政部!$A$3:$A$56=$B4)*行政部!$C$3:$C$56) -> 63401.24 | I4: =SUM(C4:H4) -> 1314057.1
B5: 2 | C5: =SUMPRODUCT((销售部!$A$3:$A$42=$B5)*销售部!$C$3:$C$42) -> 87239.89 | D5: =SUM(INDEX(市场部!$B$4:$M$9,0,$B5)) -> 152449.54 | E5: =SUMPRODUCT((后勤部!$A$4:$A$9=$B5)*后勤部!$C$4:$C$9)+SUMPRODUCT((后勤部!$E$4:$E$9=$B5)*后勤部!$G$4:$G$9) -> 26727.53 | F5: =SUMPRODUCT((人事部!$E$3:$E$38=$B5)*人事部!$C$3:$C$38) -> 632061.58 | G5: =SUMPRODUCT((TRIM(研发部!$A$3:$A$38)=$B5&"月")*研发部!$C$3:$C$38) -> 102387.56 | H5: =SUMPRODUCT((行政部!$A$3:$A$56=$B5)*行政部!$C$3:$C$56) -> 58862.04 | I5: =SUM(C5:H5) -> 1059728.1
B6: 3 | C6: =SUMPRODUCT((销售部!$A$3:$A$42=$B6)*销售部!$C$3:$C$42) -> 79553.04 | D6: =SUM(INDEX(市场部!$B$4:$M$9,0,$B6)) -> 249694.94 | E6: =SUMPRODUCT((后勤部!$A$4:$A$9=$B6)*后勤部!$C$4:$C$9)+SUMPRODUCT((后勤部!$E$4:$E$9=$B6)*后勤部!$G$4:$G$9) -> 2969.97 | F6: =SUMPRODUCT((人事部!$E$3:$E$38=$B6)*人事部!$C$3:$C$38) -> 739634.78 | G6: =SUMPRODUCT((TRIM(研发部!$A$3:$A$38)=$B6&"月")*研发部!$C$3:$C$38) -> 138456.14 | H6: =SUMPRODUCT((行政部!$A$3:$A$56=$B6)*行政部!$C$3:$C$56) -> 97866.95 | I6: =SUM(C6:H6) -> 1308175.8
B7: 4 | C7: =SUMPRODUCT((销售部!$A$3:$A$42=$B7)*销售部!$C$3:$C$42) -> 41581.42 | D7: =SUM(INDEX(市场部!$B$4:$M$9,0,$B7)) -> 319338.89 | E7: =SUMPRODUCT((后勤部!$A$4:$A$9=$B7)*后勤部!$C$4:$C$9)+SUMPRODUCT((后勤部!$E$4:$E$9=$B7)*后勤部!$G$4:$G$9) -> 26519 | F7: =SUMPRODUCT((人事部!$E$3:$E$38=$B7)*人事部!$C$3:$C$38) -> 544921.78 | G7: =SUMPRODUCT((TRIM(研发部!$A$3:$A$38)=$B7&"月")*研发部!$C$3:$C$38) -> 140983.27 | H7: =SUMPRODUCT((行政部!$A$3:$A$56=$B7)*行政部!$C$3:$C$56) -> 47744.71 | I7: =SUM(C7:H7) -> 1121089.1
B8: 5 | C8: =SUMPRODUCT((销售部!$A$3:$A$42=$B8)*销售部!$C$3:$C$42) -> 95718.63 | D8: =SUM(INDEX(市场部!$B$4:$M$9,0,$B8)) -> 209394.37 | E8: =SUMPRODUCT((后勤部!$A$4:$A$9=$B8)*后勤部!$C$4:$C$9)+SUMPRODUCT((后勤部!$E$4:$E$9=$B8)*后勤部!$G$4:$G$9) -> 16948.27 | F8: =SUMPRODUCT((人事部!$E$3:$E$38=$B8)*人事部!$C$3:$C$38) -> 737204.18 | G8: =SUMPRODUCT((TRIM(研发部!$A$3:$A$38)=$B8&"月")*研发部!$C$3:$C$38) -> 149053.75 | H8: =SUMPRODUCT((行政部!$A$3:$A$56=$B8)*行政部!$C$3:$C$56) -> 118804.28 | I8: =SUM(C8:H8) -> 1327123.5
B9: 6 | C9: =SUMPRODUCT((销售部!$A$3:$A$42=$B9)*销售部!$C$3:$C$42) -> 69257.69 | D9: =SUM(INDEX(市场部!$B$4:$M$9,0,$B9)) -> 247281.37 | E9: =SUMPRODUCT((后勤部!$A$4:$A$9=$B9)*后勤部!$C$4:$C$9)+SUMPRODUCT((后勤部!$E$4:$E$9=$B9)*后勤部!$G$4:$G$9) -> 19962.3 | F9: =SUMPRODUCT((人事部!$E$3:$E$38=$B9)*人事部!$C$3:$C$38) -> 826921.86 | G9: =SUMPRODUCT((TRIM(研发部!$A$3:$A$38)=$B9&"月")*研发部!$C$3:$C$38) -> 171509.57 | H9: =SUMPRODUCT((行政部!$A$3:$A$56=$B9)*行政部!$C$3:$C$56) -> 109098.2 | I9: =SUM(C9:H9) -> 1444031
B10: 7 | C10: =SUMPRODUCT((销售部!$A$3:$A$42=$B10)*销售部!$C$3:$C$42) -> 97456.15 | D10: =SUM(INDEX(市场部!$B$4:$M$9,0,$B10)) -> 135963.65 | E10: =SUMPRODUCT((后勤部!$A$4:$A$9=$B10)*后勤部!$C$4:$C$9)+SUMPRODUCT((后勤部!$E$4:$E$9=$B10)*后勤部!$G$4:$G$9) -> 15141.56 | F10: =SUMPRODUCT((人事部!$E$3:$E$38=$B10)*人事部!$C$3:$C$38) -> 1022440.8 | G10: =SUMPRODUCT((TRIM(研发部!$A$3:$A$38)=$B10&"月")*研发部!$C$3:$C$38) -> 124877.31 | H10: =SUMPRODUCT((行政部!$A$3:$A$56=$B10)*行政部!$C$3:$C$56) -> 112711.31 | I10: =SUM(C10:H10) -> 1508590.8
B11: 8 | C11: =SUMPRODUCT((销售部!$A$3:$A$42=$B11)*销售部!$C$3:$C$42) -> 111127.02 | D11: =SUM(INDEX(市场部!$B$4:$M$9,0,$B11)) -> 192155.9 | E11: =SUMPRODUCT((后勤部!$A$4:$A$9=$B11)*后勤部!$C$4:$C$9)+SUMPRODUCT((后勤部!$E$4:$E$9=$B11)*后勤部!$G$4:$G$9) -> 22863.77 | F11: =SUMPRODUCT((人事部!$E$3:$E$38=$B11)*人事部!$C$3:$C$38) -> 1037875.7 | G11: =SUMPRODUCT((TRIM(研发部!$A$3:$A$38)=$B11&"月")*研发部!$C$3:$C$38) -> 147637.46 | H11: =SUMPRODUCT((行政部!$A$3:$A$56=$B11)*行政部!$C$3:$C$56) -> 65594.5 | I11: =SUM(C11:H11) -> 1577254.3
B12: 9 | C12: =SUMPRODUCT((销售部!$A$3:$A$42=$B12)*销售部!$C$3:$C$42) -> 70800.34 | D12: =SUM(INDEX(市场部!$B$4:$M$9,0,$B12)) -> 327272.84 | E12: =SUMPRODUCT((后勤部!$A$4:$A$9=$B12)*后勤部!$C$4:$C$9)+SUMPRODUCT((后勤部!$E$4:$E$9=$B12)*后勤部!$G$4:$G$9) -> 14858.17 | F12: =SUMPRODUCT((人事部!$E$3:$E$38=$B12)*人事部!$C$3:$C$38) -> 540905.34 | G12: =SUMPRODUCT((TRIM(研发部!$A$3:$A$38)=$B12&"月")*研发部!$C$3:$C$38) -> 140372.03 | H12: =SUMPRODUCT((行政部!$A$3:$A$56=$B12)*行政部!$C$3:$C$56) -> 50027.27 | I12: =SUM(C12:H12) -> 1144236
B13: 10 | C13: =SUMPRODUCT((销售部!$A$3:$A$42=$B13)*销售部!$C$3:$C$42) -> 39450.15 | D13: =SUM(INDEX(市场部!$B$4:$M$9,0,$B13)) -> 171105.66 | E13: =SUMPRODUCT((后勤部!$A$4:$A$9=$B13)*后勤部!$C$4:$C$9)+SUMPRODUCT((后勤部!$E$4:$E$9=$B13)*后勤部!$G$4:$G$9) -> 2719.13 | F13: =SUMPRODUCT((人事部!$E$3:$E$38=$B13)*人事部!$C$3:$C$38) -> 474245.36 | G13: =SUMPRODUCT((TRIM(研发部!$A$3:$A$38)=$B13&"月")*研发部!$C$3:$C$38) -> 163982.68 | H13: =SUMPRODUCT((行政部!$A$3:$A$56=$B13)*行政部!$C$3:$C$56) -> 65351.88 | I13: =SUM(C13:H13) -> 916854.86
B14: 11 | C14: =SUMPRODUCT((销售部!$A$3:$A$42=$B14)*销售部!$C$3:$C$42) -> 62136.5 | D14: =SUM(INDEX(市场部!$B$4:$M$9,0,$B14)) -> 226184.36 | E14: =SUMPRODUCT((后勤部!$A$4:$A$9=$B14)*后勤部!$C$4:$C$9)+SUMPRODUCT((后勤部!$E$4:$E$9=$B14)*后勤部!$G$4:$G$9) -> 20786.18 | F14: =SUMPRODUCT((人事部!$E$3:$E$38=$B14)*人事部!$C$3:$C$38) -> 587119.59 | G14: =SUMPRODUCT((TRIM(研发部!$A$3:$A$38)=$B14&"月")*研发部!$C$3:$C$38) -> 157676.05 | H14: =SUMPRODUCT((行政部!$A$3:$A$56=$B14)*行政部!$C$3:$C$56) -> 84046.22 | I14: =SUM(C14:H14) -> 1137948.9
B15: 12 | C15: =SUMPRODUCT((销售部!$A$3:$A$42=$B15)*销售部!$C$3:$C$42) -> 81622.35 | D15: =SUM(INDEX(市场部!$B$4:$M$9,0,$B15)) -> 241765.42 | E15: =SUMPRODUCT((后勤部!$A$4:$A$9=$B15)*后勤部!$C$4:$C$9)+SUMPRODUCT((后勤部!$E$4:$E$9=$B15)*后勤部!$G$4:$G$9) -> 4658.08 | F15: =SUMPRODUCT((人事部!$E$3:$E$38=$B15)*人事部!$C$3:$C$38) -> 683140.99 | G15: =SUMPRODUCT((TRIM(研发部!$A$3:$A$38)=$B15&"月")*研发部!$C$3:$C$38) -> 154371.5 | H15: =SUMPRODUCT((行政部!$A$3:$A$56=$B15)*行政部!$C$3:$C$56) -> 39371.8 | I15: =SUM(C15:H15) -> 1204930.1
B16: 合计 | C16: =SUM(C4:C15) -> 953534.17 | D16: =SUM(D4:D15) -> 2770281 | E16: =SUM(E4:E15) -> 182863.26 | F16: =SUM(F4:F15) -> 8478067.2 | G16: =SUM(G4:G15) -> 1766393.6 | H16: =SUM(H4:H15) -> 912880.4 | I16: =SUM(I4:I15) -> 15064020

Sheet 勾稽校验
A1: 双路由勾稽：路由A=汇总视图；路由B=直接对明细表独立求和
A3: 部门 | B3: 路由A（汇总视图） | C3: 路由B（明细直加） | D3: 差额 | E3: 校验
A4: 销售部 | B4: =汇总视图!C16 -> 953534.17 | C4: =SUM(销售部!$C$3:$C$42)-SUMIF(销售部!$A$3:$A$42,"小计",销售部!$C$3:$C$42) -> 953534.17 | D4: =B4-C4 -> 0 | E4: =ABS(D4)<0.005 -> TRUE
A5: 市场部 | B5: =汇总视图!D16 -> 2770281 | C5: =SUM(市场部!$B$4:$M$9) -> 2770281 | D5: =B5-C5 -> 0 | E5: =ABS(D5)<0.005 -> TRUE
A6: 后勤部 | B6: =汇总视图!E16 -> 182863.26 | C6: =SUM(后勤部!$C$4:$C$9)+SUM(后勤部!$G$4:$G$9) -> 182863.26 | D6: =B6-C6 -> 0 | E6: =ABS(D6)<0.005 -> TRUE
A7: 人事部 | B7: =汇总视图!F16 -> 8478067.2 | C7: =SUM(人事部!$C$3:$C$38) -> 8478067.2 | D7: =B7-C7 -> 0 | E7: =ABS(D7)<0.005 -> TRUE
A8: 研发部 | B8: =汇总视图!G16 -> 1766393.6 | C8: =SUM(研发部!$C$3:$C$38) -> 1766393.6 | D8: =B8-C8 -> 0 | E8: =ABS(D8)<0.005 -> TRUE
A9: 行政部 | B9: =汇总视图!H16 -> 912880.4 | C9: =SUM(行政部!$C$3:$C$56) -> 912880.4 | D9: =B9-C9 -> 0 | E9: =ABS(D9)<0.005 -> TRUE
A11: 研发部标准科目归集（别名/空格清洗后）
A12: 标准科目 | B12: 归集金额 | C12: 校验
A13: 差旅费 | B13: =SUMPRODUCT(((TRIM(研发部!$B$3:$B$38)="出差费用")+(TRIM(研发部!$B$3:$B$38)="差旅报销")>0)*研发部!$C$3:$C$38) -> 624556.39
A14: 办公费 | B14: =SUMPRODUCT(((TRIM(研发部!$B$3:$B$38)="日常办公")+(TRIM(研发部!$B$3:$B$38)="办公用品")>0)*研发部!$C$3:$C$38) -> 596296.39
A15: 耗材费 | B15: =SUMPRODUCT(((TRIM(研发部!$B$3:$B$38)="实验耗材")+(TRIM(研发部!$B$3:$B$38)="耗材领用")>0)*研发部!$C$3:$C$38) -> 545540.77
A16: 合计 | B16: =SUM(B13:B15) -> 1766393.6 | C16: =ABS(B16-SUM(研发部!$C$3:$C$38))<0.005 -> TRUE

Sheet 销售部
A1: 销售部 2026 年费用明细（集团总部费用）
A2: 月份 | B2: 费用项目 | C2: 金额（元） | D2: 发票张数
A3: 1 | B3: 差旅费 | C3: 48222.78 | D3: 2
A4: 1 | B4: 客户维护费 | C4: 50287.43 | D4: 35
A5: 1 | B5: 运输费 | C5: 19080.78 | D5: 39
A6: 2 | B6: 差旅费 | C6: 19660.68 | D6: 12
A7: 2 | B7: 客户维护费 | C7: 50469.91 | D7: 22
A8: 2 | B8: 运输费 | C8: 17109.3 | D8: 24
A9: 3 | B9: 差旅费 | C9: 20980.94 | D9: 17
A10: 3 | B10: 客户维护费 | C10: 35206.51 | D10: 24
A11: 3 | B11: 运输费 | C11: 23365.59 | D11: 13
A12: 小计 | C12: =SUM(C9:C11) -> 79553.04
A13: 4 | B13: 差旅费 | C13: 6637.34 | D13: 31
A14: 4 | B14: 客户维护费 | C14: 872.29 | D14: 5
A15: 4 | B15: 运输费 | C15: 34071.79 | D15: 28
A16: 5 | B16: 差旅费 | C16: 53377.25 | D16: 25
A17: 5 | B17: 客户维护费 | C17: 37067.11 | D17: 1
A18: 5 | B18: 运输费 | C18: 5274.27 | D18: 1
A19: 6 | B19: 差旅费 | C19: 36508.81 | D19: 36
A20: 6 | B20: 客户维护费 | C20: 5425.84 | D20: 25
A21: 6 | B21: 运输费 | C21: 27323.04 | D21: 23
A22: 小计 | C22: =SUM(C19:C21) -> 69257.69
A23: 7 | B23: 差旅费 | C23: 38649.67 | D23: 17
A24: 7 | B24: 客户维护费 | C24: 40875.72 | D24: 14
A25: 7 | B25: 运输费 | C25: 17930.76 | D25: 19
A26: 8 | B26: 差旅费 | C26: 56629.78 | D26: 9
A27: 8 | B27: 客户维护费 | C27: 7081.92 | D27: 30
A28: 8 | B28: 运输费 | C28: 47415.32 | D28: 6
A29: 9 | B29: 差旅费 | C29: 2054.87 | D29: 27
A30: 9 | B30: 客户维护费 | C30: 9889.6 | D30: 28
A31: 9 | B31: 运输费 | C31: 58855.87 | D31: 17
A32: 小计 | C32: =SUM(C29:C31) -> 70800.34
A33: 10 | B33: 差旅费 | C33: 16263.68 | D33: 40
A34: 10 | B34: 客户维护费 | C34: 8938.45 | D34: 25
A35: 10 | B35: 运输费 | C35: 14248.02 | D35: 14
A36: 11 | B36: 差旅费 | C36: 17869.84 | D36: 30
A37: 11 | B37: 客户维护费 | C37: 17490.97 | D37: 22
A38: 11 | B38: 运输费 | C38: 26775.69 | D38: 17
A39: 12 | B39: 差旅费 | C39: 58310.81 | D39: 40
A40: 12 | B40: 客户维护费 | C40: 5628.6 | D40: 20
...

Sheet 市场部
A1: 市场部 2026 年费用明细（月份为列）
A3: 费用项目 | B3: 1 | C3: 2 | D3: 3 | E3: 4 | F3: 5 | G3: 6 | H3: 7 | I3: 8 | J3: 9 | K3: 10 | L3: 11 | M3: 12 | O3: 校验码
A4: 广告费 | B4: 65203.76 | C4: 54121.04 | D4: 41901.72 | E4: 63092.49 | F4: 26370.54 | G4: 52604.47 | H4: 23469.72 | I4: 49145.16 | J4: 47130.47 | K4: 13055.48 | L4: 30960.09 | M4: 65985.44 | O4: 6089
A5: 品牌咨询费 | B5: 50602.44 | C5: 38179.19 | D5: 45080.02 | E5: 52974.33 | F5: 60716.79 | G5: 65576.42 | H5: 31118.27 | I5: 45160.72 | J5: 69515.6 | K5: 4992.27 | L5: 46954.86 | M5: 58122.66 | O5: 5047
A6: 展会费 | B6: 27318.73 | C6: 9397.3 | D6: 23493.82 | E6: 41938.77 | F6: 8175.02 | G6: 47021.69 | H6: 30857.2 | I6: 21851.35 | J6: 72047.84 | K6: 14079.76 | L6: 37005.61 | M6: 39060.88 | O6: 9957
A7: 物料制作费 | B7: 54443.29 | C7: 2336.39 | D7: 31238.67 | E7: 10951.58 | F7: 4276.69 | G7: 47858.26 | H7: 29253.42 | I7: 11429.36 | J7: 70348.99 | K7: 20848.82 | L7: 40028.26 | M7: 20474.96 | O7: 3849
A8: 渠道佣金 | B8: 20490.36 | C8: 13326.83 | D8: 56905.23 | E8: 71704.99 | F8: 61686.03 | G8: 7900.58 | H8: 18135.18 | I8: 57098.41 | J8: 17208.18 | K8: 45159.42 | L8: 33435.28 | M8: 31213.61 | O8: 1547
A9: 短视频投放 | B9: 79615.49 | C9: 35088.79 | D9: 51075.48 | E9: 78676.73 | F9: 48169.3 | G9: 26319.95 | H9: 3129.86 | I9: 7470.9 | J9: 51021.76 | K9: 72969.91 | L9: 37800.26 | M9: 26907.87 | O9: 2354
A10: 合计 | B10: =SUM(B4:B9) -> 297674.07 | C10: =SUM(C4:C9) -> 152449.54 | D10: =SUM(D4:D9) -> 249694.94 | E10: =SUM(E4:E9) -> 319338.89 | F10: =SUM(F4:F9) -> 209394.37 | G10: =SUM(G4:G9) -> 247281.37 | H10: =SUM(H4:H9) -> 135963.65 | I10: =SUM(I4:I9) -> 192155.9 | ... M10: =SUM(M4:M9) -> 241765.42

Sheet 后勤部
A1: 后勤部 2026 年费用明细（左右两段）
A3: 月份 | B3: 费用项目 | C3: 金额（元） | E3: 月份 | F3: 费用项目 | G3: 金额（元） | I3: 备用
A4: 1 | B4: 仓储费 | C4: 8709.3 | E4: 7 | F4: 仓储费 | G4: 15141.56 | I4: 30
A5: 2 | B5: 快递费 | C5: 26727.53 | E5: 8 | F5: 快递费 | G5: 22863.77 | I5: 28
A6: 3 | B6: 燃油费 | C6: 2969.97 | E6: 9 | F6: 燃油费 | G6: 14858.17 | I6: 21
A7: 4 | B7: 仓储费 | C7: 26519 | E7: 10 | F7: 仓储费 | G7: 2719.13 | I7: 89
A8: 5 | B8: 快递费 | C8: 16948.27 | E8: 11 | F8: 快递费 | G8: 20786.18 | I8: 78
A9: 6 | B9: 燃油费 | C9: 19962.3 | E9: 12 | F9: 燃油费 | G9: 4658.08 | I9: 35

Sheet 人事部
A1: 人事部 2026 年费用明细（月份为合并单元格）
A2: 月份 | B2: 费用项目 | C2: 金额（元） | D2: 备注 | E2: 辅助
A3: 1 | B3: 工资 | C3: 156796.86 | E3: =IF(A3<>"",A3,E2) -> 1
B4: 社保公积金 | C4: 99743.05 | E4: =IF(A4<>"",A4,E3) -> 1
B5: 招聘费 | C5: 395055.34 | E5: =IF(A5<>"",A5,E4) -> 1
A6: 2 | B6: 工资 | C6: 302828.63 | E6: =IF(A6<>"",A6,E5) -> 2
B7: 社保公积金 | C7: 161996.01 | E7: =IF(A7<>"",A7,E6) -> 2
B8: 招聘费 | C8: 167236.94 | E8: =IF(A8<>"",A8,E7) -> 2
A9: 3 | B9: 工资 | C9: 376781.54 | E9: =IF(A9<>"",A9,E8) -> 3
B10: 社保公积金 | C10: 328057.74 | E10: =IF(A10<>"",A10,E9) -> 3
B11: 招聘费 | C11: 34795.5 | E11: =IF(A11<>"",A11,E10) -> 3
A12: 4 | B12: 工资 | C12: 132331.44 | E12: =IF(A12<>"",A12,E11) -> 4
B13: 社保公积金 | C13: 251284.97 | E13: =IF(A13<>"",A13,E12) -> 4
B14: 招聘费 | C14: 161305.37 | E14: =IF(A14<>"",A14,E13) -> 4
A15: 5 | B15: 工资 | C15: 202414.65 | E15: =IF(A15<>"",A15,E14) -> 5
B16: 社保公积金 | C16: 350909.44 | E16: =IF(A16<>"",A16,E15) -> 5
B17: 招聘费 | C17: 183880.09 | E17: =IF(A17<>"",A17,E16) -> 5
A18: 6 | B18: 工资 | C18: 385819.37 | E18: =IF(A18<>"",A18,E17) -> 6
B19: 社保公积金 | C19: 108012.18 | E19: =IF(A19<>"",A19,E18) -> 6
B20: 招聘费 | C20: 333090.31 | E20: =IF(A20<>"",A20,E19) -> 6
A21: 7 | B21: 工资 | C21: 339465.9 | E21: =IF(A21<>"",A21,E20) -> 7
B22: 社保公积金 | C22: 293835.44 | E22: =IF(A22<>"",A22,E21) -> 7
B23: 招聘费 | C23: 389139.5 | E23: =IF(A23<>"",A23,E22) -> 7
A24: 8 | B24: 工资 | C24: 364280.91 | E24: =IF(A24<>"",A24,E23) -> 8
B25: 社保公积金 | C25: 328756.1 | E25: =IF(A25<>"",A25,E24) -> 8
B26: 招聘费 | C26: 344838.64 | E26: =IF(A26<>"",A26,E25) -> 8
A27: 9 | B27: 工资 | C27: 95667.35 | E27: =IF(A27<>"",A27,E26) -> 9
B28: 社保公积金 | C28: 336604.61 | E28: =IF(A28<>"",A28,E27) -> 9
B29: 招聘费 | C29: 108633.38 | E29: =IF(A29<>"",A29,E28) -> 9
A30: 10 | B30: 工资 | C30: 383627.57 | E30: =IF(A30<>"",A30,E29) -> 10
B31: 社保公积金 | C31: 65925.75 | E31: =IF(A31<>"",A31,E30) -> 10
B32: 招聘费 | C32: 24692.04 | E32: =IF(A32<>"",A32,E31) -> 10
A33: 11 | B33: 工资 | C33: 95775.48 | E33: =IF(A33<>"",A33,E32) -> 11
B34: 社保公积金 | C34: 108816.69 | E34: =IF(A34<>"",A34,E33) -> 11
B35: 招聘费 | C35: 382527.42 | E35: =IF(A35<>"",A35,E34) -> 11
A36: 12 | B36: 工资 | C36: 235648.61 | E36: =IF(A36<>"",A36,E35) -> 12
B37: 社保公积金 | C37: 71673.93 | E37: =IF(A37<>"",A37,E36) -> 12
B38: 招聘费 | C38: 375818.45 | E38: =IF(A38<>"",A38,E37) -> 12

Sheet 研发部
A1: 研发部 2026 年费用明细（标签未清洗）
A2: 月份 | B2: 费用项目 | C2: 金额（元）
A3: 1月 | B3: 耗材领用 | C3: 64805.64
A4: 1月 | B4: 差旅报销 | C4: 87578.97
A5: 1月 | B5: 日常办公 | C5: 22701.62
A6: 2月 | B6: 实验耗材 | C6: 45786.6
A7: 2月 | B7: 差旅报销 | C7: 24221.59
A8: 2月 | B8: 办公用品 | C8: 32379.37
A9: 3月 | B9: 实验耗材 | C9: 52200.46
A10: 3月 | B10: 差旅报销 | C10: 56890.39
A11: 3月 | B11: 日常办公 | C11: 29365.29
A12: 4月 | B12: 实验耗材 | C12: 11158.34
A13: 4月 | B13: 出差费用 | C13: 82986.12
A14: 4月 | B14: 办公用品 | C14: 46838.81
... A38: 12月 | B38: 办公用品 | C38: 62734.41

Sheet 行政部
A1: 行政部 2026 年费用明细（含红字冲销）
A2: 月份 | B2: 费用项目 | C2: 金额（元） | D2: 凭证数
A3: 8 | B3: 物业费 | C3: 33533.34 | D3: 3
A4: 11 | B4: 车辆使用费 | C4: 29348.47 | D4: 1
A5: 1 | B5: 绿植租摆 | C5: 20505.42 | D5: 1
A6: 3 | B6: 水电费 | C6: 25192.48 | D6: 3
A7: 5 | B7: 水电费 | C7: 44406.06 | D7: 1
A8: 8 | B8: 车辆使用费 | C8: -2813.79 | D8: 2
A9: 12 | B9: 物业费 | C9: 28473.84 | D9: 1
A10: 9 | B10: 车辆使用费 | C10: 28912.93 | D10: 3
A11: 5 | B11: 绿植租摆 | C11: 32437.44 | D11: 3
A12: 12 | B12: 绿植租摆 | C12: 822.06 | D12: 3
A13: 11 | B13: 绿植租摆 | C13: 11316.92 | D13: 1
A14: 10 | B14: 水电费 | C14: 16139.11 | D14: 2
... A56: 6 | B56: 物业费 | C56: 39056.54 | D56: 1

Sheet 科目对照
A1: 标准科目 | B1: 写法一 | C1: 写法二
A2: 差旅费 | B2: 出差费用 | C2: 差旅报销
A3: 办公费 | B3: 日常办公 | C3: 办公用品
A4: 耗材费 | B4: 实验耗材 | C4: 耗材领用
